Workbook

Sheet Model
A1: Live wedding watercolour — cost & pricing model
A2: A5 cotton-rag guest keepsakes · painted live · capped per night · Sydney · AUD, excl GST
A3: Blue cells are mine to change. Black cells are calculated. Everything is painted live; I do not post overflow afterward, so I sell a number I can comfortably hit.
A5: TIME & THROUGHPUT
A6: Reception painting hours | B6: 5
A7: Setup + pack-down (hours) | B7: 1
A8: Finished pieces per painting hour | B8: 4.5 | C8: Watercolour A5 of 1–4 guests. Benchmarks ~4–6/hr. My real ceiling.
A9: Studio touch-up per piece (minutes) | B9: 8 | C9: Light finishing only, since everything is done on the night.
A10: Consultation + admin per wedding (hours) | B10: 3
A11: Travel time, round trip (hours) | B11: 1.5
A13: Theoretical max pieces (hours × pace) | B13: =B6*B8 -> 22.5
A14: Pieces I commit to (the cap I sell) | B14: 20 | C14: Set below the max so a slow patch never breaks the promise. This drives my costs and price.
A15: Average guests per piece | B15: 2 | C15: Group shots of 1–4; 2 is a fair average.
A16: Guests covered, approx | B16: =B14*B15 -> 40 | C16: A chosen subset of the room, not everyone. The honest number to quote couples.
A17: Studio touch-up hours | B17: =B14*B9/60 -> 2.6666667
A18: Total engaged hours per wedding | B18: =B6+B7+B17+B10+B11 -> 13.166667
A20: MATERIALS PER PIECE
A21: A5 cotton-rag sheet | B21: 2.5 | C21: Per A5 once I cut full sheets. Update after a batch.
A22: Paint + incidentals | B22: 0.8
A23: Clear sleeve + backing board | B23: 1.2
A24: Branded mount / folder | B24: 1.5
A25: Materials per piece | B25: =SUM(B21:B24) -> 6
A26: Spare prepped sheets (%) | B26: 0.1 | C26: Paper I prep and may not use; covers mistakes and a couple of extras.
A28: PER-WEDDING COSTS
A29: Couple keepsake piece — framing | B29: 90
A30: Travel cost (fuel / tolls / parking) | B30: 60
A31: Use an assistant? | B31: No | C31: An assistant on photos + queue + sleeving lets me push the cap up on bigger nights.
A32: Assistant fee (if used) | B32: 250
A33: Assistant cost applied | B33: =IF(B31="Yes",B32,0) -> 0
A34: Public liability insurance (per event) | B34: 25
A35: Marketing / Instagram (amortised) | B35: 60
A36: Misc admin + consumables | B36: 20
A37: Booking / card fees (% of price) | B37: 0.0175
A39: PRICE I'M TESTING
A40: Package price to couple | B40: 2400 | C40: Set this, read margin and hourly below. Compare tiers on the Packages tab.
A42: MY TARGETS
A43: Target effective hourly rate | B43: 100
A44: Target gross margin | B44: 0.65
A46: RESULTS
A47: Total materials (committed + spares) | B47: =B14*(1+B26)*B25 -> 132
...

Sheet Packages
A1: My packages — capped, all live
A2: Three tiers by how many pieces I commit to paint on the night. Same cost base as the Model tab; I set price, hours, pace, cap and assistant per column.
B4: Intimate | C4: Full reception | D4: Large (assistant)
A5: Package price (set this) | B5: 1500 | C5: 2400 | D5: 3400
A6: Reception painting hours | B6: 4 | C6: 5 | D6: 6
A7: Pieces per painting hour | B7: 4.5 | C7: 4.5 | D7: 5
A8: Pieces I commit to (cap) | B8: 16 | C8: 20 | D8: 28
A9: Assistant on this tier? | B9: No | C9: No | D9: Yes
A10: Average guests per piece | B10: 2 | C10: 2 | D10: 2
A11: Guests covered, approx | B11: =B8*B10 -> 32 | C11: =C8*C10 -> 40 | D11: =D8*D10 -> 56
A12: Total engaged hours | B12: =B6+Model!$B$7+(B8*Model!$B$9/60)+Model!$B$10+Model!$B$11 -> 11.633333 | C12: =C6+Model!$B$7+(C8*Model!$B$9/60)+Model!$B$10+Model!$B$11 -> 13.166667 | D12: =D6+Model!$B$7+(D8*Model!$B$9/60)+Model!$B$10+Model!$B$11 -> 15.233333
A13: Materials (committed + spares) | B13: =B8*(1+Model!$B$26)*Model!$B$25 -> 105.6 | C13: =C8*(1+Model!$B$26)*Model!$B$25 -> 132 | D13: =D8*(1+Model!$B$26)*Model!$B$25 -> 184.8
A14: Assistant cost | B14: =IF(B9="Yes",Model!$B$32,0) -> 0 | C14: =IF(C9="Yes",Model!$B$32,0) -> 0 | D14: =IF(D9="Yes",Model!$B$32,0) -> 250
A15: Other per-wedding costs (excl fees) | B15: =Model!$B$29+Model!$B$30+Model!$B$34+Model!$B$35+Model!$B$36 -> 255 | C15: =Model!$B$29+Model!$B$30+Model!$B$34+Model!$B$35+Model!$B$36 -> 255 | D15: =Model!$B$29+Model!$B$30+Model!$B$34+Model!$B$35+Model!$B$36 -> 255
A16: Booking / card fees | B16: =B5*Model!$B$37 -> 26.25 | C16: =C5*Model!$B$37 -> 42 | D16: =D5*Model!$B$37 -> 59.5
A17: Total cost per wedding | B17: =B13+B14+B15+B16 -> 386.85 | C17: =C13+C14+C15+C16 -> 429 | D17: =D13+D14+D15+D16 -> 749.3
A18: Gross profit | B18: =B5-B17 -> 1113.15 | C18: =C5-C17 -> 1971 | D18: =D5-D17 -> 2650.7
A19: Gross margin | B19: =B18/B5 -> 0.7421 | C19: =C18/C5 -> 0.82125 | D19: =D18/D5 -> 0.77961765
A20: Effective hourly rate | B20: =B18/B12 -> 95.686246 | C20: =C18/C12 -> 149.6962 | D20: =D18/D12 -> 174.00656
A21: Revenue per piece | B21: =B5/B8 -> 93.75 | C21: =C5/C8 -> 120 | D21: =D5/D8 -> 121.42857
A22: Price per guest covered | B22: =B5/B11 -> 46.875 | C22: =C5/C11 -> 60 | D22: =D5/D11 -> 60.714286
A24: Guests covered is a subset I quote honestly. Priority tokens for the couple's closest people keep the queue fair once I hit the cap.
A25: Green = clears target · Amber = close · Red = below floor. Targets live on the Model tab.

Sheet Benchmarks
A1: Market benchmarks I pulled (June 2026)
A2: Live event painting and guest-portrait pricing. As advertised; most exclude travel.
A4: Artist / source | B4: Market | C4: Format | D4: Price (advertised) | E4: Throughput | F4: Source
A5: Golden Rose Creative | B5: Northern NSW | C5: A5 watercolour guest portraits | D5: Custom quote | E5: 5 couples (10 guests)/hr; up to 40 guests in 4 hrs | F5: goldenrosecreative.co
A6: Christine Pan | B6: Sydney | C6: A5–A4 live illustration | D6: From $1,245 (intro) | E6: Studio finish for overflow | F6: christinepan.com.au
A7: Grace Choi | B7: Sydney | C7: Live guest portraits | D7: From $2,500; range $1,200–$6,000 | E7: ~12–15 illustrations/hr (line) | F7: gracechoiartist.com
A8: Let Me Draw You | B8: Sydney | C8: Live guest illustration | D8: From $600 / 3 hrs | E8: ~5–7 min per portrait | F8: letmedrawyou.com
A9: Lisa Catanea | B9: Sydney | C9: Live illustration + A4 couple piece | D9: From $1,400 | E9: Hourly available | F9: lisacatanea.com.au
A10: Wedding Guest Portraits | B10: Sydney | C10: Live guest portraits | D10: $1,000 half / $2,000 full day | E10: 4 hr / 8 hr | F10: weddingguestportraits.com.au
A11: Painted Favours | B11: Sydney | C11: Canvas + guest illustrations | D11: Custom quote | E11: 60+ pieces a night with assistant | F11: paintedfavours.com.au
A12: IAmPoppy Designs | B12: Sydney/national | C12: Watercolour or acrylic canvas | D12: Package, framing incl. | E12: 6–8 hrs live + 6–12 hrs studio | F12: iampoppy.com
A13: Aust. market (survey blog) | B13: Australia | C13: Live painting (canvas) | D13: Avg $2,500–$5,000; ~$500–$700/hr | E13: — | F13: elenavalerie.com.au
A14: weddingillustrator.co.uk | B14: UK | C14: A5 watercolour guest portraits | D14: Package (multi-hr) | E14: 8 singles / 5 couples / 2–3 families per hr | F14: weddingillustrator.co.uk
A15: Arty at Heart | B15: UK | C15: A5–A4 watercolour, groups up to 4 | D15: +£100/hr over 5-hr base | E15: 4–5 pieces/hr | F15: artyatheartillustrations.com
A16: US market (survey blogs) | B16: USA | C16: Live painting (canvas) | D16: $2,000–$10,000; median ~$2,500 | E16: 3–4 hrs on site + studio | F16: paintmyweddingday.com; benkeys.com
A18: Note: 'illustration' usually means fast line work (12–15/hr). Watercolour of 1–4 guests is slower and more premium, which is where my capped A5 pieces sit.
