Workbook

Sheet Model
A1: Live wedding watercolour — cost & pricing model
A2: A5 cotton-rag group portraits · Sydney · all figures AUD, excl GST
A3: Blue cells are mine to change. Black cells are calculated — I update the blue inputs and everything below refreshes.
A5: TIME & THROUGHPUT
A6: Reception painting hours | B6: 5 | C6: My leading format is painting through the night.
A7: Setup + pack-down (hours) | B7: 1
A8: Finished pieces per painting hour | B8: 4.5 | C8: Watercolour A5 of 1–4 guests. Benchmarks sit at ~4–6/hr; revisit once I know my real pace.
A9: Studio refining per piece (minutes) | B9: 10
A10: Consultation + admin per wedding (hours) | B10: 3
A11: Travel time, round trip (hours) | B11: 1.5
A13: Pieces per night | B13: =B6*B8 -> 22.5
A14: Studio refining hours | B14: =B13*B9/60 -> 3.75
A15: Total engaged hours per wedding | B15: =B6+B7+B14+B10+B11 -> 14.25 | C15: On-site + setup + studio refining + consult/admin + travel.
A17: MATERIALS PER PIECE
A18: A5 cotton-rag sheet | B18: 2.5 | C18: Cost of one A5, cut from full cotton-rag sheets. Update after I cut a batch and know my yield.
A19: Paint + incidentals | B19: 0.8
A20: Clear sleeve + backing board | B20: 1.2
A21: Branded mount / folder | B21: 1.5 | C21: Set to 0 if a piece goes out bare in a sleeve.
A22: Materials per piece | B22: =SUM(B18:B21) -> 6
A24: PER-WEDDING COSTS
A25: Couple keepsake piece — framing | B25: 90 | C25: The couple's own framed piece I include in the package.
A26: Travel cost (fuel / tolls / parking) | B26: 60
A27: Use an assistant? | B27: No | C27: An assistant on photos + queue + sleeving lifts my throughput and is worth modelling for big nights.
A28: Assistant fee (if used) | B28: 250
A29: Assistant cost applied | B29: =IF(B27="Yes",B28,0) -> 0
A30: Public liability insurance (per event) | B30: 25 | C30: Annual premium spread across the weddings I expect to paint that year.
A31: Marketing / Instagram (amortised) | B31: 60
A32: Misc admin + consumables | B32: 20
A33: Booking / card fees (% of price) | B33: 0.0175
A35: PRICE I'M TESTING
A36: Package price to couple | B36: 2400 | C36: Set this, then read the margin and effective hourly below. Compare options on the Scenarios tab.
A38: MY TARGETS
A39: Target effective hourly rate | B39: 100 | C39: What my engaged time needs to earn for this to be worth it.
A40: Target gross margin | B40: 0.65
A42: RESULTS
A43: Total materials (all pieces) | B43: =B13*B22 -> 135
A44: Couple keepsake framing | B44: =B25 -> 90
A45: Travel | B45: =B26 -> 60
A46: Assistant | B46: =B29 -> 0
A47: Insurance | B47: =B30 -> 25
...

Sheet Scenarios
A1: Pricing scenarios — launch → target
A2: Same cost base as the Model tab. I only change price, hours and pace per column.
B4: Launch (foundation rate) | C4: Settling in | D4: Target standing
A5: Package price (set per column) | B5: 1400 | C5: 1900 | D5: 2800
A6: Reception painting hours | B6: 4 | C6: 5 | D6: 5
A7: Pieces per painting hour | B7: 4 | C7: 4.5 | D7: 5
A8: Pieces per night | B8: =B6*B7 -> 16 | C8: =C6*C7 -> 22.5 | D8: =D6*D7 -> 25
A9: Total engaged hours | B9: =B6+Model!$B$7+(B8*Model!$B$9/60)+Model!$B$10+Model!$B$11 -> 12.166667 | C9: =C6+Model!$B$7+(C8*Model!$B$9/60)+Model!$B$10+Model!$B$11 -> 14.25 | D9: =D6+Model!$B$7+(D8*Model!$B$9/60)+Model!$B$10+Model!$B$11 -> 14.666667
A10: Materials (all pieces) | B10: =B8*Model!$B$22 -> 96 | C10: =C8*Model!$B$22 -> 135 | D10: =D8*Model!$B$22 -> 150
A11: Other per-wedding costs (excl fees) | B11: =Model!$B$25+Model!$B$26+Model!$B$29+Model!$B$30+Model!$B$31+Model!$B$32 -> 255 | C11: =Model!$B$25+Model!$B$26+Model!$B$29+Model!$B$30+Model!$B$31+Model!$B$32 -> 255 | D11: =Model!$B$25+Model!$B$26+Model!$B$29+Model!$B$30+Model!$B$31+Model!$B$32 -> 255
A12: Booking / card fees | B12: =B5*Model!$B$33 -> 24.5 | C12: =C5*Model!$B$33 -> 33.25 | D12: =D5*Model!$B$33 -> 49
A13: Total cost per wedding | B13: =B10+B11+B12 -> 375.5 | C13: =C10+C11+C12 -> 423.25 | D13: =D10+D11+D12 -> 454
A14: Gross profit | B14: =B5-B13 -> 1024.5 | C14: =C5-C13 -> 1476.75 | D14: =D5-D13 -> 2346
A15: Gross margin | B15: =B14/B5 -> 0.73178571 | C15: =C14/C5 -> 0.77723684 | D15: =D14/D5 -> 0.83785714
A16: Effective hourly rate | B16: =B14/B9 -> 84.205479 | C16: =C14/C9 -> 103.63158 | D16: =D14/D9 -> 159.95455
A17: Revenue per piece | B17: =B5/B8 -> 87.5 | C17: =C5/C8 -> 84.444444 | D17: =D5/D8 -> 112
A19: Green = clears my target · Amber = close · Red = below floor. Targets live on the Model tab.

Sheet Benchmarks
A1: Market benchmarks I pulled (June 2026)
A2: Live event painting and guest-portrait pricing. Figures as advertised; most exclude travel. I'll refresh these periodically.
A4: Artist / source | B4: Market | C4: Format | D4: Price (advertised) | E4: Throughput | F4: Source
A5: Golden Rose Creative | B5: Northern NSW | C5: A5 watercolour guest portraits | D5: Custom quote | E5: 5 couples (10 guests)/hr; up to 40 guests in 4 hrs | F5: goldenrosecreative.co/live-wedding-illustrations
A6: Christine Pan | B6: Sydney | C6: A5–A4 live illustration | D6: From $1,245 (intro) | E6: Studio finish for overflow | F6: christinepan.com.au
A7: Grace Choi | B7: Sydney | C7: Live guest portraits | D7: From $2,500; range $1,200–$6,000 | E7: ~12–15 illustrations/hr (line) | F7: gracechoiartist.com/weddings
A8: Let Me Draw You | B8: Sydney | C8: Live guest illustration | D8: From $600 / 3 hrs | E8: ~5–7 min per portrait | F8: letmedrawyou.com
A9: Lisa Catanea | B9: Sydney | C9: Live illustration + A4 couple piece | D9: From $1,400 | E9: Hourly available | F9: lisacatanea.com.au
A10: Wedding Guest Portraits | B10: Sydney | C10: Live guest portraits | D10: $1,000 half day / $2,000 full day | E10: 4 hr / 8 hr | F10: weddingguestportraits.com.au
A11: Painted Favours | B11: Sydney | C11: Canvas + guest illustrations | D11: Custom quote | E11: 60+ pieces a night with assistant | F11: paintedfavours.com.au
A12: IAmPoppy Designs | B12: Sydney/national | C12: Watercolour or acrylic canvas | D12: Package, framing incl. | E12: 6–8 hrs live + 6–12 hrs studio | F12: iampoppy.com
A13: Wedding Painter (Mina Lee) | B13: Sydney | C13: Oil canvas + live illustration add-on | D13: Canvas $4,900–$7,500 | E13: Up to 7 hrs + 40–60 hrs studio | F13: easyweddings.com.au
A14: Aust. market (survey blog) | B14: Australia | C14: Live painting (canvas) | D14: Avg $2,500–$5,000; ~$500–$700/hr | E14: — | F14: elenavalerie.com.au
A15: weddingillustrator.co.uk | B15: UK | C15: A5 full-length watercolour guest portraits | D15: Package (multi-hr) | E15: 8 singles / 5 couples / 2–3 families per hr | F15: weddingillustrator.co.uk
... A17: US market (survey blogs) | B17: USA | C17: Live painting (canvas) | D17: Typically $2,000–$10,000; median ~$2,500 | E17: 3–4 hrs on site + up to 40–60 hrs studio | F17: paintmyweddingday.com; benkeys.com
A19: Note: 'illustration' usually means fast line/fashion work (12–15/hr). Watercolour of 1–4 guests is slower and more premium, which is where my A5 cotton-rag pieces sit.
